Workbook

Sheet dataset
A2: DAFTAR NAMA KEPALA KELUARGA PENERIMA PKH DESA SEMANDING
A3: RT. 1 & RT. 2 RW.05 KEC SEMANDING KAB TUBAN 2021
A5: No. | B5: No KK | C5: Nama Kepala Keluarga | D5: RT / RW | E5: Penghasilan | F5: Luas Rumah | G5: Status Kepemilikan Rumah | H5: Sumber Air | I5: ibu Hamil / menyusui | J5: lansia | K5: jumlah tanggungan (Anak) | L5: jenis dinding | M5: jenis lantai | N5: jenis atap | O5: Keputusan
A6: 1 | B6: 3523151708700001 | C6: MUHAMMAD ABIDIN | D6: 01 / 05 | E6: 1500000 | F6: 72 M2 | G6: Milik Sendiri | H6: PDAM | I6: Tidak Ada | J6: Tidak Ada | K6: 1 | L6: Tembok | M6: Keramik | N6: Genteng | O6: Tidak
A7: 2 | B7: 3523151403061494 | C7: MULYONO | D7: 01 / 05 | E7: 1500000 | F7: 54 M2 | G7: Milik Sendiri | H7: PDAM | I7: Tidak Ada | J7: 1 | K7: Tidak Ada | L7: Tembok | M7: Keramik | N7: Genteng | O7: Tidak
A8: 3 | B8: 3523150803680008 | C8: CAMPUN | D8: 01 / 05 | E8: 3500000 | F8: 54 M2 | G8: Milik Sendiri | H8: PDAM | I8: Tidak Ada | J8: Tidak Ada | K8: Tidak Ada | L8: Tembok | M8: Keramik | N8: Genteng | O8: Tidak
A9: 4 | B9: 3523152312110002 | C9: SUNTONO | D9: 01 / 05 | E9: 1500000 | F9: 54 M2 | G9: Milik Sendiri | H9: PDAM | I9: Tidak Ada | J9: Tidak ada | K9: 1 | L9: Tembok | M9: Keramik | N9: Genteng | O9: Tidak
A10: 5 | B10: =Penghasilan!B21 -> 3523151309090186 | C10: DEDDY MUDHIATAMA | D10: 02 / 05 | E10: =Penghasilan!D21 -> 5000000 | F10: 90 M2 | G10: Milik Sendiri | H10: PDAM | I10: Tidak Ada | J10: Tidak Ada | K10: 2 | L10: Tembok | M10: Keramik | N10: Genteng | O10: Tidak
A11: 6 | B11: 3523153010120005 | C11: IWAN SUGIYANTO | D11: 01 / 05 | E11: 3500000 | F11: 90 M2 | G11: Milik Sendiri | H11: PDAM | I11: Tidak Ada | J11: Tidak Ada | K11: 1 | L11: Tembok | M11: Keramik | N11: Genteng | O11: Tidak
A12: 7 | B12: 3523151005780008 | C12: MUNIR MUSTAQIM | D12: 01 / 05 | E12: 2000000 | F12: 90 M2 | G12: Milik Sendiri | H12: PDAM | I12: Tidak Ada | J12: 1 | K12: 2 | L12: Tembok | M12: Keramik | N12: Genteng | O12: Tidak
A13: 8 | B13: 3523155002670004 | C13: KASMINI | D13: 01 / 05 | E13: 1500000 | F13: 72 M2 | G13: Milik Sendiri | H13: PDAM | I13: Tidak Ada | J13: Tidak Ada | K13: 1 | L13: Tembok | M13: Keramik | N13: Genteng | O13: Tidak
A14: 9 | B14: =Penghasilan!B67 -> 3523122711140001 | C14: MOKH YUSUF | D14: 01 / 05 | E14: =Penghasilan!D67 -> 1500000 | F14: 80 M2 | G14: Menumpang | H14: PDAM | I14: Tidak Ada | J14: Tidak Ada | K14: 2 | L14: Tembok | M14: Keramik | N14: Genteng | O14: Tidak
A15: 10 | B15: 3523151403061495 | C15: TARNO | D15: 01 / 05 | E15: 1500000 | F15: 90 M2 | G15: Milik Sendiri | H15: PDAM | I15: Tidak Ada | J15: 2 | K15: Tidak Ada | L15: Tembok | M15: Keramik | N15: Genteng | O15: Layak
A16: 11 | B16: 3523151403061490 | C16: MURSID | D16: 01 / 05 | E16: Tidak bekerja | F16: 56 M2 | G16: Milik Sendiri | H16: PDAM | I16: Tidak Ada | J16: 2 | K16: Tidak Ada | L16: Papan/ Kayu | M16: Semen | N16: Asbes / Seng | O16: Layak
A17: 12 | B17: 3523151403061489 | C17: ABDUL MAJID | D17: 01 / 05 | E17: 1500000 | F17: 90 M2 | G17: Milik Sendiri | H17: PDAM | I17: Tidak Ada | J17: 2 | K17: Tidak Ada | L17: Tembok | M17: Keramik | N17: Genteng | O17: Tidak
A18: 13 | B18: 3523151210160002 | C18: SUGENG WAHONO | D18: 01 / 05 | E18: 2000000 | F18: 90 M2 | G18: Menumpang | H18: PDAM | I18: Tidak Ada | J18: Tidak Ada | K18: 2 | L18: Tembok | M18: Keramik | N18: Genteng | O18: Tidak
A19: 14 | B19: 3523153012090392 | C19: TAMIN | D19: 01 / 05 | E19: 1500000 | F19: 48 M2 | G19: Milik Sendiri | H19: PDAM | I19: Tidak Ada | J19: Tidak Ada | K19: 1 | L19: Tembok | M19: Semen | N19: Genteng | O19: Tidak
A20: 15 | B20: 3523153112090174 | C20: ABDUH NAHLIAN | D20: 01 / 05 | E20: 2500000 | F20: 48 M2 | G20: Milik Sendiri | H20: PDAM | I20: Tidak Ada | J20: Tidak Ada | K20: 2 | L20: Tembok | M20: Keramik | N20: Genteng | O20: Tidak
A21: 16 | B21: 3523151403061485 | C21: TARMUDJI | D21: 01 / 05 | E21: 1500000 | F21: 54 M2 | G21: Milik Sendiri | H21: PDAM | I21: Tidak Ada | J21: 2 | K21: Tidak Ada | L21: Tembok | M21: Keramik | N21: Genteng | O21: Tidak
A22: 17 | B22: 3523150305120003 | C22: SUWANTO | D22: 01 / 05 | E22: 1500000 | F22: 32 M2 | G22: Milik Sendiri | H22: PDAM | I22: Tidak Ada | J22: Tidak Ada | K22: 2 | L22: Papan/Bambu | M22: Semen | N22: Genteng | O22: Layak
A23: 18 | B23: 3523153112090228 | C23: KASIMO | D23: 01 / 05 | E23: 1500000 | F23: 45 M2 | G23: Milik Sendiri | H23: PDAM | I23: Tidak Ada | J23: Tidak Ada | K23: 2 | L23: Papan / kayu | M23: Semen | N23: Genteng | O23: layak
A24: 19 | B24: 3523152608190006 | C24: KASMINAH | D24: 01 / 05 | E24: 1000000 | F24: 56 M2 | G24: Milik Sendiri | H24: PDAM | I24: Tidak Ada | J24: 1 | K24: Tidak Ada | L24: Tembok | M24: Semen | N24: Genteng | O24: Layak
A25: 20 | B25: 3523150603820007 | C25: DIDIK PRIANTO | D25: 01 / 05 | E25: 1500000 | F25: 54 M2 | G25: Milik Sendiri | H25: PDAM | I25: Tidak Ada | J25: Tidak Ada | K25: 1 | L25: Tembok | M25: Semen | N25: Genteng | O25: Tidak
A26: 21 | B26: 3523151403061487 | C26: DASMIATI | D26: 01 / 05 | E26: Tidak bekerja | F26: 42 M2 | G26: Milik Sendiri | H26: PDAM | I26: Tidak Ada | J26: 1 | K26: Tidak Ada | L26: Tembok | M26: Semen | N26: Genteng | O26: Layak
A27: 22 | B27: 3523153112090184 | C27: IMAM KHOIRI | D27: 01 / 05 | E27: 6000000 | F27: 54M2 | G27: Milik Sendiri | H27: PDAM | I27: Tidak Ada | J27: Tidak Ada | K27: 3 | L27: Tembok | M27: Keramik | N27: Genteng | O27: Tidak
A28: 23 | B28: 3523151403061482 | C28: IMAM TOKO | D28: 01 / 05 | E28: 1500000 | F28: 54 M2 | G28: Milik Sendiri | H28: PDAM | I28: Tidak Ada | J28: Tidak Ada | K28: 2 | L28: Tembok | M28: Keramik | N28: Genteng | O28: Tidak
A29: 24 | B29: 3523150212140009 | C29: TUTIK | D29: 01 / 05 | E29: 2000000 | F29: 40 M2 | G29: Milik Sendiri | H29: PDAM | I29: Tidak Ada | J29: Tidak Ada | K29: 3 | L29: Tembok | M29: Keramik | N29: Genteng | O29: Tidak
A30: 25 | B30: 3523151403061478 | C30: RAKIJAH | D30: 01 / 05 | E30: Tidak bekerja | F30: 35 M2 | G30: Milik Sendiri | H30: PDAM | I30: Tidak Ada | J30: 1 | K30: Tidak Ada | L30: Tembok | M30: Semen | N30: Genteng | O30: Layak
A31: 26 | B31: 3523151403061480 | C31: SARDI | D31: 01 / 05 | E31: 1000000 | F31: 60 M2 | G31: Milik Sendiri | H31: PDAM | I31: Tidak Ada | J31: 2 | K31: Tidak Ada | L31: Tembok | M31: Keramik | N31: Genteng | O31: Tidak
A32: 27 | B32: 3523150507190002 | C32: KASLIK | D32: 01 / 05 | E32: 1500000 | F32: 60 M2 | G32: Menumpang | H32: PDAM | I32: Tidak Ada | J32: Tidak Ada | K32: 3 | L32: Tembok | M32: Keramik | N32: Genteng | O32: Tidak
A33: 28 | B33: 3523152906120007 | C33: TOTOK AGUSTARI | D33: 01 / 05 | E33: 2000000 | F33: 60 M2 | G33: Milik Sendiri | H33: PDAM | I33: Tidak Ada | J33: Tidak Ada | K33: 1 | L33: Tembok | M33: Semen | N33: Genteng | O33: Tidak
A34: 29 | B34: 3523151403061479 | C34: WASIR | D34: 01 / 05 | E34: 3000000 | F34: 40 M2 | G34: Milik Sendiri | H34: PDAM | I34: Tidak Ada | J34: Tidak Ada | K34: Tidak Ada | L34: Tembok | M34: Keramik | N34: Genteng | O34: Tidak
A35: 30 | B35: 3523151403061477 | C35: SUDIRO | D35: 01 / 05 | E35: Tidak bekerja | F35: 48 M2 | G35: Milik Sendiri | H35: PDAM | I35: Tidak Ada | J35: 2 | K35: 2 | L35: Bambu | M35: Tanah | N35: Genteng | O35: Layak
A36: 31 | B36: 3523153112090244 | C36: SUYANTO | D36: 01 / 05 | E36: 1500000 | F36: 24 M2 | G36: Milik Sendiri | H36: PDAM | I36: Tidak Ada | J36: Tidak Ada | K36: 1 | L36: Tembok | M36: Semen | N36: Genteng | O36: Layak
A37: 32 | B37: 3523141108840001 | C37: SUWANDI | D37: 01 / 05 | E37: 2000000 | F37: 52 M2 | G37: Milik Sendiri | H37: PDAM | I37: Tidak Ada | J37: Tidak Ada | K37: 2 | L37: Tembok | M37: Keramik | N37: Beton | O37: Tidak
A38: 33 | B38: 3523150107580287 | C38: LIK DJOYO | D38: 01 / 05 | E38: Tidak bekerja | F38: 53 M2 | G38: Menumpang | H38: PDAM | I38: Tidak Ada | J38: 1 | K38: Tidak Ada | L38: Tembok | M38: Keramik | N38: Beton | O38: Tidak
A39: 34 | B39: 3523150202500002 | C39: KARMADI | D39: 01 / 05 | E39: 2500000 | F39: 50 M2 | G39: Milik Sendiri | H39: PDAM | I39: Tidak Ada | J39: 2 | K39: Tidak Ada | L39: Tembok | M39: Keramik | N39: Genteng | O39: Tidak
A40: 35 | B40: 3523150107510085 | C40: WIBOWO SLAMET | D40: 01 / 05 | E40: Tidak bekerja | F40: 54 M2 | G40: Milik Sendiri | H40: Sumur | I40: Tidak Ada | J40: 1 | K40: Tidak Ada | L40: Papan / kayu | M40: Tanah | N40: Genteng | O40: Layak
A41: 36 | B41: 3523151604600002 | C41: WINARTO | D41: 01 / 05 | E41: 1500000 | F41: 54 M2 | G41: Milik Sendiri | H41: PDAM | I41: Tidak Ada | J41: Tidak Ada | K41: Tidak Ada | L41: Tembok | M41: Keramik | N41: Genteng | O41: Tidak
A42: 37 | B42: 3523152603110001 | C42: HADI | D42: 01 / 05 | E42: 2000000 | F42: 54 M2 | G42: Milik Sendiri | H42: PDAM | I42: Tidak Ada | J42: Tidak Ada | K42: 2 | L42: Tembok | M42: Keramik | N42: Genteng | O42: Tidak
...

Sheet Penghasilan
A3: DAFTAR NO KK DESA SEMANDING RT 02 RW5 | H3: Daftar Nama yang berkerja lebih dari 1 orang dalam 1 KK
A5: No | B5: No KK | C5: Nama Kepala Keluarga | D5: Penghasilan | E5: RT / RW | H5: No KK | I5: Nama | J5: Penghasilan
A6: 1 | B6: 3523151309090184 | C6: JUATMUN | D6: =8400000/12 -> 700000 | E6: 2 / 5 | H6: =B8 -> 3523151403061499 | I6: TARMUDO | J6: =18000000/12 -> 1500000
A7: 2 | B7: 3523152906120006 | C7: YONO | D7: =12000000/12 -> 1000000 | E7: 2 / 5 | H7: =B12 -> 3523151403061490 | I7: SETYAWAN | J7: =12000000/12 -> 1000000
A8: 3 | B8: 3523151403061499 | C8: KARNADI | D8: =24000000/12 -> 2000000 | E8: 2 / 5 | H8: =B17 -> 3523151403060761 | I8: M. INDRA SAPUTRA | J8: =48000000/12 -> 4000000
A9: 4 | B9: 3523151403061502 | C9: SAKRUN | D9: 1500000 | E9: 2 / 5
A10: 5 | B10: 3523151403061500 | C10: MULYONO | D10: =6000000/12 -> 500000 | E10: 2 / 5
A11: 6 | B11: 3523151403061497 | C11: SUKARDI | D11: 800000 | E11: 2 / 5
A12: 7 | B12: 3523151403061490 | C12: WARJANI | D12: =6000000/12 -> 500000 | E12: 2/ 5
A13: 8 | B13: 3523151008120009 | C13: MOCHMMAD ISWANDI | D13: =12000000/12 -> 1000000 | E13: 2 / 5
A14: 9 | B14: 3523152110200008 | C14: RUJU ALIP | D14: =18000000/12 -> 1500000 | E14: 2 / 5
A15: 10 | B15: 3523151403060759 | C15: SUTARTI | D15: =12000000/12 -> 1000000 | E15: 2 / 5
A16: 11 | B16: 3523150508150003 | C16: DIDIK PURNOMO | D16: =12000000/12 -> 1000000 | E16: 2 / 5
A17: 12 | B17: 3523151403060761 | C17: GENDUT HARIYANTO | D17: =60000000/12 -> 5000000 | E17: 2 / 5
A18: 13 | B18: 3523152007120012 | C18: DHIQ PRIHADI | D18: =21600000/12 -> 1800000 | E18: 2 / 5
A19: 14 | B19: 3523152901190003 | C19: SUTARSIH | D19: =24000000/12 -> 2000000 | E19: 2 / 5
A20: 15 | B20: 3523151409180003 | C20: DWI PURWANTO | D20: =36000000/12 -> 3000000 | E20: 2 / 5
A21: 16 | B21: 3523151309090186 | C21: DEDY MUDHIATAMA | D21: =60000000/12 -> 5000000 | E21: 2 / 5
A22: 17 | B22: 3523151309090178 | C22: MAMPUANTO | D22: =12000000/12 -> 1000000 | E22: 2 / 5
A23: 18 | B23: 3523151503061503 | C23: ASTRO DJOYO WARAS | D23: 666000 | E23: 2 / 5
A24: 19 | B24: 3523151403061467 | C24: WARIYANTO | D24: =12000000/12 -> 1000000 | E24: 2 / 5
A25: 20 | B25: 3523150311160031 | C25: HENDRA PRAMANA TEGUH | D25: =24000000/12 -> 2000000 | E25: 2 / 5
A26: 21 | B26: 3523151309090126 | C26: MOH. MAHKIN NAUFAL | D26: =36000000/12 -> 3000000 | E26: 2 / 5
A27: 22 | B27: 3523151403060779 | C27: PATMI | D27: Tidak bekerja | E27: 2 / 5
A28: 23 | B28: 3523152111210007 | C28: ARIF SULISTIONO | D28: =12000000/12 -> 1000000 | E28: 2 / 5
A29: 24 | B29: 3523153112090187 | C29: SAMSI | D29: =24000000/12 -> 2000000 | E29: 2 / 5
A30: 25 | B30: 3523151403061463 | C30: MUNASIR | D30: 800000 | E30: 2 / 5
A31: 26 | B31: 3523151403060769 | C31: PUJI PRASTYO | D31: =36000000/12 -> 3000000 | E31: 2/ 5
A32: 27 | B32: 3523151005110001 | C32: PURWANTO | D32: =12000000/12 -> 1000000 | E32: 2 / 5
A33: 28 | B33: 3523151403060778 | C33: PANLIK | D33: =12000000/12 -> 1000000 | E33: 2 / 5
A34: 29 | B34: 3523151403061462 | C34: MARSILAN | D34: =12000000/12 -> 1000000 | E34: 2/ 5
A35: 30 | B35: 3523151303180005 | C35: MACTIUS RICKY L. | D35: =36000000/12 -> 3000000 | E35: 2 / 5
A36: 31 | B36: 3523151309090180 | C36: SUMIJAH | D36: Tidak bekerja | E36: 2 / 5
A37: 32 | B37: 3523151403061466 | C37: SUJONO | D37: 800000 | E37: 2 / 5
A38: 33 | B38: 3523151403061468 | C38: SUPRAPTO | D38: =18000000/12 -> 1500000 | E38: 2 / 5
A39: 34 | B39: 3523151403060780 | C39: SAMIDAH | D39: Tidak bekerja | E39: 2 / 5
A40: 35 | B40: 3523150209200001 | C40: NURHAMID | D40: =60000000/12 -> 5000000 | E40: 2 / 5
A41: 36 | B41: 3523153004190006 | C41: SUHARTONO | D41: =30000000/12 -> 2500000 | E41: 2 / 5
A42: 37 | B42: 3523151309090188 | C42: SUGIYONO | D42: =18000000/12 -> 1500000 | E42: 2/ 5
A43: 38 | B43: 3523152405190001 | C43: TRI ABDUL AZIZ | D43: =12000000/12 -> 1000000 | E43: 2 / 5
...

Sheet B.kriteria & R.kecocokan
A2: A. Rating Kecocokan kriteria dan Bobot
E3: NB : bobot dari kriteria tersebut diambil dari jurnal
A4: tabel jenis kriteria
A6: Kriteria | B6: Jenis Variabel | C6: Bobot
A7: =dataset!E5 -> Penghasilan | B7: Benefit | C7: 2
A8: =dataset!F5 -> Luas Rumah | B8: Benefit | C8: 1.5
A9: =dataset!G5 -> Status Kepemilikan Rumah | B9: Benefit | C9: 1
A10: =dataset!H5 -> Sumber Air | B10: Benefit | C10: 0.5
A11: =dataset!I5 -> ibu Hamil / menyusui | B11: Cost | C11: 0.5
A12: =dataset!J5 -> lansia | B12: Cost | C12: 0.5
A13: =dataset!L5 -> jenis dinding | B13: Benefit | C13: 1
A14: =dataset!M5 -> jenis lantai | B14: Benefit | C14: 1
A15: =dataset!K5 -> jumlah tanggungan (Anak) | B15: Cost | C15: 0.5
A16: (Sumber : Pratiwi dkk (2019))
A18: B. Tabel rating kecocokan kriteria
A20: Kriteria Penghasilan
A22: Kriteria | B22: Klasifikasi | C22: Nilai
A23: > 2.000.000 | B23: Banyak | C23: 2.5
A24: 1.500.000 - 2.000.000 | B24: Cukup | C24: 5
A25: 0 - 1.500.000 | B25: Sedikit | C25: 7.5
A26: (Sumber : Pratiwi dkk (2019))
A28: Kriteria luas Rumah
A30: Kriteria | B30: Klasifikasi | C30: Nilai
A31: > 500 m2 | B31: Sangat Rendah | C31: 1
A32: 201 - 500 m2 | B32: Rendah | C32: 2.5
A33: 101 - 200 m2 | B33: Sedang | C33: 5
A34: 51 - 100 m2 | B34: Tinggi | C34: 7.5
A35: 0 - 50 m2 | B35: Sangat Tinggi | C35: 10
A36: (Sumber : Pratiwi dkk (2019))
A38: kriteria Status Kepemilikan Rumah
A40: Kriteria | B40: Klasifikasi | C40: Nilai
A41: Milik Sendiri | B41: Rendah | C41: 2.5
A42: Sewa | B42: Sedang | C42: 5
A43: Menumpang | B43: Tinggi | C43: 7.5
A44: (Sumber : Pratiwi dkk (2019))
A46: Kriteria jenis dinding
A48: Kriteria | B48: Klasifikasi | C48: Nilai
A49: Tembok / Bata | B49: Rendah | C49: 2.5
A50: Papan / Kayu | B50: Sedang | C50: 5
A51: Papan / Bambu | B51: Tinggi | C51: 7.5
...

Sheet t data &hitung c4.5
A1: TRANSFORMASI DATA & SELEKSI DATA
A3: No. | B3: No KK | C3: Nama Kepala Keluarga | D3: RT / RW | E3: Penghasilan | F3: Luas Rumah | G3: Status Kepemilikan Rumah | H3: Sumber Air | I3: ibu Hamil / menyusui | J3: lansia | K3: jumlah tanggungan (Anak) | L3: jenis dinding | M3: jenis lantai | N3: jenis atap | O3: Keputusan | P3: Keputusan 2
A4: 1 | B4: 3523151708700001 | C4: MUHAMMAD ABIDIN | D4: 01 / 05 | E4: ='B.kriteria & R.kecocokan'!$B$24 -> Cukup | F4: ='B.kriteria & R.kecocokan'!$B$34 -> Tinggi | G4: ='B.kriteria & R.kecocokan'!$B$41 -> Rendah | H4: ='B.kriteria & R.kecocokan'!$B$72 -> Rendah | I4: ='B.kriteria & R.kecocokan'!$B$95 -> Rendah | J4: ='B.kriteria & R.kecocokan'!$B$80 -> Rendah | K4: ='B.kriteria & R.kecocokan'!$B$89 -> Sedikit | L4: ='B.kriteria & R.kecocokan'!$B$49 -> Rendah | M4: ='B.kriteria & R.kecocokan'!$B$57 -> Rendah | N4: ='B.kriteria & R.kecocokan'!$B$65 -> Rendah | O4: Tidak
A5: 2 | B5: 3523151403061494 | C5: MULYONO | D5: 01 / 05 | E5: ='B.kriteria & R.kecocokan'!$B$24 -> Cukup | F5: ='B.kriteria & R.kecocokan'!$B$34 -> Tinggi | G5: ='B.kriteria & R.kecocokan'!$B$41 -> Rendah | H5: ='B.kriteria & R.kecocokan'!$B$72 -> Rendah | I5: ='B.kriteria & R.kecocokan'!$B$95 -> Rendah | J5: ='B.kriteria & R.kecocokan'!$B$81 -> Tinggi | K5: ='B.kriteria & R.kecocokan'!$B$90 -> Sangat Sedikit | L5: ='B.kriteria & R.kecocokan'!$B$49 -> Rendah | M5: ='B.kriteria & R.kecocokan'!$B$57 -> Rendah | N5: ='B.kriteria & R.kecocokan'!$B$65 -> Rendah | O5: Tidak
A6: 3 | B6: 3523150803680008 | C6: CAMPUN | D6: 01 / 05 | E6: ='B.kriteria & R.kecocokan'!$B$23 -> Banyak | F6: ='B.kriteria & R.kecocokan'!$B$34 -> Tinggi | G6: ='B.kriteria & R.kecocokan'!$B$41 -> Rendah | H6: ='B.kriteria & R.kecocokan'!$B$72 -> Rendah | I6: ='B.kriteria & R.kecocokan'!$B$95 -> Rendah | J6: ='B.kriteria & R.kecocokan'!$B$80 -> Rendah | K6: ='B.kriteria & R.kecocokan'!$B$90 -> Sangat Sedikit | L6: ='B.kriteria & R.kecocokan'!$B$49 -> Rendah | M6: ='B.kriteria & R.kecocokan'!$B$57 -> Rendah | N6: ='B.kriteria & R.kecocokan'!$B$65 -> Rendah | O6: Tidak
A7: 4 | B7: 3523152312110002 | C7: SUNTONO | D7: 01 / 05 | E7: ='B.kriteria & R.kecocokan'!$B$24 -> Cukup | F7: ='B.kriteria & R.kecocokan'!$B$34 -> Tinggi | G7: ='B.kriteria & R.kecocokan'!$B$41 -> Rendah | H7: ='B.kriteria & R.kecocokan'!$B$72 -> Rendah | I7: ='B.kriteria & R.kecocokan'!$B$95 -> Rendah | J7: ='B.kriteria & R.kecocokan'!$B$80 -> Rendah | K7: ='B.kriteria & R.kecocokan'!$B$89 -> Sedikit | L7: ='B.kriteria & R.kecocokan'!$B$49 -> Rendah | M7: ='B.kriteria & R.kecocokan'!$B$57 -> Rendah | N7: ='B.kriteria & R.kecocokan'!$B$65 -> Rendah | O7: Tidak
A8: 5 | B8: =Penghasilan!B19 -> 3523152901190003 | C8: DEDDY MUDHIATAMA | D8: 02 / 05 | E8: ='B.kriteria & R.kecocokan'!$B$24 -> Cukup | F8: ='B.kriteria & R.kecocokan'!$B$34 -> Tinggi | G8: ='B.kriteria & R.kecocokan'!$B$41 -> Rendah | H8: ='B.kriteria & R.kecocokan'!$B$72 -> Rendah | I8: ='B.kriteria & R.kecocokan'!$B$95 -> Rendah | J8: ='B.kriteria & R.kecocokan'!$B$80 -> Rendah | K8: ='B.kriteria & R.kecocokan'!$B$88 -> Sedang | L8: ='B.kriteria & R.kecocokan'!$B$49 -> Rendah | M8: ='B.kriteria & R.kecocokan'!$B$57 -> Rendah | N8: ='B.kriteria & R.kecocokan'!$B$65 -> Rendah | O8: Tidak
A9: 6 | B9: 3523153010120005 | C9: IWAN SUGIYANTO | D9: 01 / 05 | E9: ='B.kriteria & R.kecocokan'!$B$23 -> Banyak | F9: ='B.kriteria & R.kecocokan'!$B$34 -> Tinggi | G9: ='B.kriteria & R.kecocokan'!$B$41 -> Rendah | H9: ='B.kriteria & R.kecocokan'!$B$72 -> Rendah | I9: ='B.kriteria & R.kecocokan'!$B$95 -> Rendah | J9: ='B.kriteria & R.kecocokan'!$B$80 -> Rendah | K9: ='B.kriteria & R.kecocokan'!$B$89 -> Sedikit | L9: ='B.kriteria & R.kecocokan'!$B$49 -> Rendah | M9: ='B.kriteria & R.kecocokan'!$B$57 -> Rendah | N9: ='B.kriteria & R.kecocokan'!$B$65 -> Rendah | O9: Tidak
A10: 7 | B10: 3523151005780008 | C10: MUNIR MUSTAQIM | D10: 01 / 05 | E10: ='B.kriteria & R.kecocokan'!$B$23 -> Banyak | F10: ='B.kriteria & R.kecocokan'!$B$34 -> Tinggi | G10: ='B.kriteria & R.kecocokan'!$B$41 -> Rendah | H10: ='B.kriteria & R.kecocokan'!$B$72 -> Rendah | I10: ='B.kriteria & R.kecocokan'!$B$95 -> Rendah | J10: ='B.kriteria & R.kecocokan'!$B$81 -> Tinggi | K10: ='B.kriteria & R.kecocokan'!$B$88 -> Sedang | L10: ='B.kriteria & R.kecocokan'!$B$49 -> Rendah | M10: ='B.kriteria & R.kecocokan'!$B$57 -> Rendah | N10: ='B.kriteria & R.kecocokan'!$B$65 -> Rendah | O10: Tidak
A11: 8 | B11: 3523155002670004 | C11: KASMINI | D11: 01 / 05 | E11: ='B.kriteria & R.kecocokan'!$B$24 -> Cukup | F11: ='B.kriteria & R.kecocokan'!$B$34 -> Tinggi | G11: ='B.kriteria & R.kecocokan'!$B$41 -> Rendah | H11: ='B.kriteria & R.kecocokan'!$B$72 -> Rendah | I11: ='B.kriteria & R.kecocokan'!$B$95 -> Rendah | J11: ='B.kriteria & R.kecocokan'!$B$80 -> Rendah | K11: ='B.kriteria & R.kecocokan'!$B$89 -> Sedikit | L11: ='B.kriteria & R.kecocokan'!$B$49 -> Rendah | M11: ='B.kriteria & R.kecocokan'!$B$57 -> Rendah | N11: ='B.kriteria & R.kecocokan'!$B$65 -> Rendah | O11: Tidak
A12: 9 | B12: =Penghasilan!B67 -> 3523122711140001 | C12: MOKH YUSUF | D12: 01 / 05 | E12: ='B.kriteria & R.kecocokan'!$B$24 -> Cukup | F12: ='B.kriteria & R.kecocokan'!$B$34 -> Tinggi | G12: ='B.kriteria & R.kecocokan'!B43 -> Tinggi | H12: ='B.kriteria & R.kecocokan'!$B$72 -> Rendah | I12: ='B.kriteria & R.kecocokan'!$B$95 -> Rendah | J12: ='B.kriteria & R.kecocokan'!$B$80 -> Rendah | K12: ='B.kriteria & R.kecocokan'!$B$88 -> Sedang | L12: ='B.kriteria & R.kecocokan'!$B$49 -> Rendah | M12: ='B.kriteria & R.kecocokan'!$B$57 -> Rendah | N12: ='B.kriteria & R.kecocokan'!$B$65 -> Rendah | O12: Tidak
A13: 10 | B13: 3523151403061495 | C13: TARNO | D13: 01 / 05 | E13: ='B.kriteria & R.kecocokan'!$B$24 -> Cukup | F13: ='B.kriteria & R.kecocokan'!$B$34 -> Tinggi | G13: ='B.kriteria & R.kecocokan'!$B$41 -> Rendah | H13: ='B.kriteria & R.kecocokan'!$B$72 -> Rendah | I13: ='B.kriteria & R.kecocokan'!$B$95 -> Rendah | J13: ='B.kriteria & R.kecocokan'!$B$81 -> Tinggi | K13: ='B.kriteria & R.kecocokan'!$B$90 -> Sangat Sedikit | L13: ='B.kriteria & R.kecocokan'!$B$49 -> Rendah | M13: ='B.kriteria & R.kecocokan'!$B$57 -> Rendah | N13: ='B.kriteria & R.kecocokan'!$B$65 -> Rendah | O13: Layak
A14: 11 | B14: 3523151403061490 | C14: MURSID | D14: 01 / 05 | E14: ='B.kriteria & R.kecocokan'!$B$25 -> Sedikit | F14: ='B.kriteria & R.kecocokan'!$B$34 -> Tinggi | G14: ='B.kriteria & R.kecocokan'!$B$41 -> Rendah | H14: ='B.kriteria & R.kecocokan'!$B$72 -> Rendah | I14: ='B.kriteria & R.kecocokan'!$B$95 -> Rendah | J14: ='B.kriteria & R.kecocokan'!$B$81 -> Tinggi | K14: ='B.kriteria & R.kecocokan'!$B$90 -> Sangat Sedikit | L14: ='B.kriteria & R.kecocokan'!$B$50 -> Sedang | M14: ='B.kriteria & R.kecocokan'!$B$58 -> Sedang | N14: ='B.kriteria & R.kecocokan'!$B$66 -> Sedang | O14: Layak
A15: 12 | B15: 3523151403061489 | C15: ABDUL MAJID | D15: 01 / 05 | E15: ='B.kriteria & R.kecocokan'!$B$24 -> Cukup | F15: ='B.kriteria & R.kecocokan'!$B$34 -> Tinggi | G15: ='B.kriteria & R.kecocokan'!$B$41 -> Rendah | H15: ='B.kriteria & R.kecocokan'!$B$72 -> Rendah | I15: ='B.kriteria & R.kecocokan'!$B$95 -> Rendah | J15: ='B.kriteria & R.kecocokan'!$B$81 -> Tinggi | K15: ='B.kriteria & R.kecocokan'!$B$90 -> Sangat Sedikit | L15: ='B.kriteria & R.kecocokan'!$B$49 -> Rendah | M15: ='B.kriteria & R.kecocokan'!$B$57 -> Rendah | N15: ='B.kriteria & R.kecocokan'!$B$65 -> Rendah | O15: Tidak
A16: 13 | B16: 3523151210160002 | C16: SUGENG WAHONO | D16: 01 / 05 | E16: ='B.kriteria & R.kecocokan'!$B$24 -> Cukup | F16: ='B.kriteria & R.kecocokan'!$B$34 -> Tinggi | G16: ='B.kriteria & R.kecocokan'!$B$43 -> Tinggi | H16: ='B.kriteria & R.kecocokan'!$B$72 -> Rendah | I16: ='B.kriteria & R.kecocokan'!$B$95 -> Rendah | J16: ='B.kriteria & R.kecocokan'!$B$80 -> Rendah | K16: ='B.kriteria & R.kecocokan'!$B$88 -> Sedang | L16: ='B.kriteria & R.kecocokan'!$B$49 -> Rendah | M16: ='B.kriteria & R.kecocokan'!$B$57 -> Rendah | N16: ='B.kriteria & R.kecocokan'!$B$65 -> Rendah | O16: Tidak
A17: 14 | B17: 3523153012090392 | C17: TAMIN | D17: 01 / 05 | E17: ='B.kriteria & R.kecocokan'!$B$24 -> Cukup | F17: ='B.kriteria & R.kecocokan'!$B$35 -> Sangat Tinggi | G17: ='B.kriteria & R.kecocokan'!$B$41 -> Rendah | H17: ='B.kriteria & R.kecocokan'!$B$72 -> Rendah | I17: ='B.kriteria & R.kecocokan'!$B$95 -> Rendah | J17: ='B.kriteria & R.kecocokan'!$B$80 -> Rendah | K17: ='B.kriteria & R.kecocokan'!$B$89 -> Sedikit | L17: ='B.kriteria & R.kecocokan'!$B$49 -> Rendah | M17: ='B.kriteria & R.kecocokan'!$B$58 -> Sedang | N17: ='B.kriteria & R.kecocokan'!$B$65 -> Rendah | O17: Tidak
A18: 15 | B18: 3523153112090174 | C18: ABDUH NAHLIAN | D18: 01 / 05 | E18: ='B.kriteria & R.kecocokan'!$B$23 -> Banyak | F18: ='B.kriteria & R.kecocokan'!$B$35 -> Sangat Tinggi | G18: ='B.kriteria & R.kecocokan'!$B$41 -> Rendah | H18: ='B.kriteria & R.kecocokan'!$B$72 -> Rendah | I18: ='B.kriteria & R.kecocokan'!$B$95 -> Rendah | J18: ='B.kriteria & R.kecocokan'!$B$80 -> Rendah | K18: ='B.kriteria & R.kecocokan'!$B$88 -> Sedang | L18: ='B.kriteria & R.kecocokan'!$B$49 -> Rendah | M18: ='B.kriteria & R.kecocokan'!$B$57 -> Rendah | N18: ='B.kriteria & R.kecocokan'!$B$65 -> Rendah | O18: Tidak
A19: 16 | B19: 3523151403061485 | C19: TARMUDJI | D19: 01 / 05 | E19: ='B.kriteria & R.kecocokan'!$B$24 -> Cukup | F19: ='B.kriteria & R.kecocokan'!$B$34 -> Tinggi | G19: ='B.kriteria & R.kecocokan'!$B$41 -> Rendah | H19: ='B.kriteria & R.kecocokan'!$B$72 -> Rendah | I19: ='B.kriteria & R.kecocokan'!$B$95 -> Rendah | J19: ='B.kriteria & R.kecocokan'!$B$81 -> Tinggi | K19: ='B.kriteria & R.kecocokan'!$B$90 -> Sangat Sedikit | L19: ='B.kriteria & R.kecocokan'!$B$49 -> Rendah | M19: ='B.kriteria & R.kecocokan'!$B$57 -> Rendah | N19: ='B.kriteria & R.kecocokan'!$B$65 -> Rendah | O19: Tidak
A20: 17 | B20: 3523150305120003 | C20: SUWANTO | D20: 01 / 05 | E20: ='B.kriteria & R.kecocokan'!$B$24 -> Cukup | F20: ='B.kriteria & R.kecocokan'!$B$35 -> Sangat Tinggi | G20: ='B.kriteria & R.kecocokan'!$B$41 -> Rendah | H20: ='B.kriteria & R.kecocokan'!$B$72 -> Rendah | I20: ='B.kriteria & R.kecocokan'!$B$95 -> Rendah | J20: ='B.kriteria & R.kecocokan'!$B$80 -> Rendah | K20: ='B.kriteria & R.kecocokan'!$B$88 -> Sedang | L20: ='B.kriteria & R.kecocokan'!$B$51 -> Tinggi | M20: ='B.kriteria & R.kecocokan'!$B$58 -> Sedang | N20: ='B.kriteria & R.kecocokan'!$B$65 -> Rendah | O20: Layak
A21: 18 | B21: 3523153112090228 | C21: KASIMO | D21: 01 / 05 | E21: ='B.kriteria & R.kecocokan'!$B$24 -> Cukup | F21: ='B.kriteria & R.kecocokan'!$B$35 -> Sangat Tinggi | G21: ='B.kriteria & R.kecocokan'!$B$41 -> Rendah | H21: ='B.kriteria & R.kecocokan'!$B$72 -> Rendah | I21: ='B.kriteria & R.kecocokan'!$B$95 -> Rendah | J21: ='B.kriteria & R.kecocokan'!$B$80 -> Rendah | K21: ='B.kriteria & R.kecocokan'!$B$88 -> Sedang | L21: ='B.kriteria & R.kecocokan'!$B$50 -> Sedang | M21: ='B.kriteria & R.kecocokan'!$B$58 -> Sedang | N21: ='B.kriteria & R.kecocokan'!$B$65 -> Rendah | O21: Layak
A22: 19 | B22: 3523152608190006 | C22: KASMINAH | D22: 01 / 05 | E22: ='B.kriteria & R.kecocokan'!$B$25 -> Sedikit | F22: ='B.kriteria & R.kecocokan'!$B$34 -> Tinggi | G22: ='B.kriteria & R.kecocokan'!$B$41 -> Rendah | H22: ='B.kriteria & R.kecocokan'!$B$72 -> Rendah | I22: ='B.kriteria & R.kecocokan'!$B$95 -> Rendah | J22: ='B.kriteria & R.kecocokan'!$B$81 -> Tinggi | K22: ='B.kriteria & R.kecocokan'!$B$90 -> Sangat Sedikit | L22: ='B.kriteria & R.kecocokan'!$B$49 -> Rendah | M22: ='B.kriteria & R.kecocokan'!$B$58 -> Sedang | N22: ='B.kriteria & R.kecocokan'!$B$65 -> Rendah | O22: Layak
A23: 20 | B23: 3523150603820007 | C23: DIDIK PRIANTO | D23: 01 / 05 | E23: ='B.kriteria & R.kecocokan'!$B$24 -> Cukup | F23: ='B.kriteria & R.kecocokan'!$B$34 -> Tinggi | G23: ='B.kriteria & R.kecocokan'!$B$41 -> Rendah | H23: ='B.kriteria & R.kecocokan'!$B$72 -> Rendah | I23: ='B.kriteria & R.kecocokan'!$B$95 -> Rendah | J23: ='B.kriteria & R.kecocokan'!$B$80 -> Rendah | K23: ='B.kriteria & R.kecocokan'!$B$89 -> Sedikit | L23: ='B.kriteria & R.kecocokan'!$B$49 -> Rendah | M23: ='B.kriteria & R.kecocokan'!$B$58 -> Sedang | N23: ='B.kriteria & R.kecocokan'!$B$65 -> Rendah | O23: Tidak
A24: 21 | B24: 3523151403061487 | C24: DASMIATI | D24: 01 / 05 | E24: ='B.kriteria & R.kecocokan'!$B$25 -> Sedikit | F24: ='B.kriteria & R.kecocokan'!$B$35 -> Sangat Tinggi | G24: ='B.kriteria & R.kecocokan'!$B$41 -> Rendah | H24: ='B.kriteria & R.kecocokan'!$B$72 -> Rendah | I24: ='B.kriteria & R.kecocokan'!$B$95 -> Rendah | J24: ='B.kriteria & R.kecocokan'!$B$81 -> Tinggi | K24: ='B.kriteria & R.kecocokan'!$B$90 -> Sangat Sedikit | L24: ='B.kriteria & R.kecocokan'!$B$49 -> Rendah | M24: ='B.kriteria & R.kecocokan'!$B$58 -> Sedang | N24: ='B.kriteria & R.kecocokan'!$B$65 -> Rendah | O24: Layak
A25: 22 | B25: 3523153112090184 | C25: IMAM KHOIRI | D25: 01 / 05 | E25: ='B.kriteria & R.kecocokan'!$B$23 -> Banyak | F25: ='B.kriteria & R.kecocokan'!$B$34 -> Tinggi | G25: ='B.kriteria & R.kecocokan'!$B$41 -> Rendah | H25: ='B.kriteria & R.kecocokan'!$B$72 -> Rendah | I25: ='B.kriteria & R.kecocokan'!$B$95 -> Rendah | J25: ='B.kriteria & R.kecocokan'!$B$80 -> Rendah | K25: ='B.kriteria & R.kecocokan'!$B$88 -> Sedang | L25: ='B.kriteria & R.kecocokan'!$B$49 -> Rendah | M25: ='B.kriteria & R.kecocokan'!$B$57 -> Rendah | N25: ='B.kriteria & R.kecocokan'!$B$65 -> Rendah | O25: Tidak
A26: 23 | B26: 3523151403061482 | C26: IMAM TOKO | D26: 01 / 05 | E26: ='B.kriteria & R.kecocokan'!$B$24 -> Cukup | F26: ='B.kriteria & R.kecocokan'!$B$34 -> Tinggi | G26: ='B.kriteria & R.kecocokan'!$B$41 -> Rendah | H26: ='B.kriteria & R.kecocokan'!$B$72 -> Rendah | I26: ='B.kriteria & R.kecocokan'!$B$95 -> Rendah | J26: ='B.kriteria & R.kecocokan'!$B$80 -> Rendah | K26: ='B.kriteria & R.kecocokan'!$B$88 -> Sedang | L26: ='B.kriteria & R.kecocokan'!$B$49 -> Rendah | M26: ='B.kriteria & R.kecocokan'!$B$57 -> Rendah | N26: ='B.kriteria & R.kecocokan'!$B$65 -> Rendah | O26: Tidak
A27: 24 | B27: 3523150212140009 | C27: TUTIK | D27: 01 / 05 | E27: ='B.kriteria & R.kecocokan'!$B$24 -> Cukup | F27: ='B.kriteria & R.kecocokan'!$B$35 -> Sangat Tinggi | G27: ='B.kriteria & R.kecocokan'!$B$41 -> Rendah | H27: ='B.kriteria & R.kecocokan'!$B$72 -> Rendah | I27: ='B.kriteria & R.kecocokan'!$B$95 -> Rendah | J27: ='B.kriteria & R.kecocokan'!$B$80 -> Rendah | K27: ='B.kriteria & R.kecocokan'!$B$88 -> Sedang | L27: ='B.kriteria & R.kecocokan'!$B$49 -> Rendah | M27: ='B.kriteria & R.kecocokan'!$B$57 -> Rendah | N27: ='B.kriteria & R.kecocokan'!$B$65 -> Rendah | O27: Tidak
A28: 25 | B28: 3523151403061478 | C28: RAKIJAH | D28: 01 / 05 | E28: ='B.kriteria & R.kecocokan'!$B$25 -> Sedikit | F28: ='B.kriteria & R.kecocokan'!$B$35 -> Sangat Tinggi | G28: ='B.kriteria & R.kecocokan'!$B$41 -> Rendah | H28: ='B.kriteria & R.kecocokan'!$B$72 -> Rendah | I28: ='B.kriteria & R.kecocokan'!$B$95 -> Rendah | J28: ='B.kriteria & R.kecocokan'!$B$81 -> Tinggi | K28: ='B.kriteria & R.kecocokan'!$B$90 -> Sangat Sedikit | L28: ='B.kriteria & R.kecocokan'!$B$49 -> Rendah | M28: ='B.kriteria & R.kecocokan'!$B$58 -> Sedang | N28: ='B.kriteria & R.kecocokan'!$B$65 -> Rendah | O28: Layak
A29: 26 | B29: 3523151403061480 | C29: SARDI | D29: 01 / 05 | E29: ='B.kriteria & R.kecocokan'!$B$25 -> Sedikit | F29: ='B.kriteria & R.kecocokan'!$B$34 -> Tinggi | G29: ='B.kriteria & R.kecocokan'!$B$41 -> Rendah | H29: ='B.kriteria & R.kecocokan'!$B$72 -> Rendah | I29: ='B.kriteria & R.kecocokan'!$B$95 -> Rendah | J29: ='B.kriteria & R.kecocokan'!$B$81 -> Tinggi | K29: ='B.kriteria & R.kecocokan'!$B$90 -> Sangat Sedikit | L29: ='B.kriteria & R.kecocokan'!$B$49 -> Rendah | M29: ='B.kriteria & R.kecocokan'!$B$57 -> Rendah | N29: ='B.kriteria & R.kecocokan'!$B$65 -> Rendah | O29: Tidak
A30: 27 | B30: 3523150507190002 | C30: KASLIK | D30: 01 / 05 | E30: ='B.kriteria & R.kecocokan'!$B$24 -> Cukup | F30: ='B.kriteria & R.kecocokan'!$B$34 -> Tinggi | G30: ='B.kriteria & R.kecocokan'!$B$43 -> Tinggi | H30: ='B.kriteria & R.kecocokan'!$B$72 -> Rendah | I30: ='B.kriteria & R.kecocokan'!$B$95 -> Rendah | J30: ='B.kriteria & R.kecocokan'!$B$80 -> Rendah | K30: ='B.kriteria & R.kecocokan'!$B$88 -> Sedang | L30: ='B.kriteria & R.kecocokan'!$B$49 -> Rendah | M30: ='B.kriteria & R.kecocokan'!$B$57 -> Rendah | N30: ='B.kriteria & R.kecocokan'!$B$65 -> Rendah | O30: Tidak
A31: 28 | B31: 3523152906120007 | C31: TOTOK AGUSTARI | D31: 01 / 05 | E31: ='B.kriteria & R.kecocokan'!$B$24 -> Cukup | F31: ='B.kriteria & R.kecocokan'!$B$34 -> Tinggi | G31: ='B.kriteria & R.kecocokan'!$B$41 -> Rendah | H31: ='B.kriteria & R.kecocokan'!$B$72 -> Rendah | I31: ='B.kriteria & R.kecocokan'!$B$95 -> Rendah | J31: ='B.kriteria & R.kecocokan'!$B$80 -> Rendah | K31: ='B.kriteria & R.kecocokan'!$B$89 -> Sedikit | L31: ='B.kriteria & R.kecocokan'!$B$49 -> Rendah | M31: ='B.kriteria & R.kecocokan'!$B$58 -> Sedang | N31: ='B.kriteria & R.kecocokan'!$B$65 -> Rendah | O31: Tidak
A32: 29 | B32: 3523151403061479 | C32: WASIR | D32: 01 / 05 | E32: ='B.kriteria & R.kecocokan'!$B$23 -> Banyak | F32: ='B.kriteria & R.kecocokan'!$B$35 -> Sangat Tinggi | G32: ='B.kriteria & R.kecocokan'!$B$41 -> Rendah | H32: ='B.kriteria & R.kecocokan'!$B$72 -> Rendah | I32: ='B.kriteria & R.kecocokan'!$B$95 -> Rendah | J32: ='B.kriteria & R.kecocokan'!$B$80 -> Rendah | K32: ='B.kriteria & R.kecocokan'!$B$90 -> Sangat Sedikit | L32: ='B.kriteria & R.kecocokan'!$B$49 -> Rendah | M32: ='B.kriteria & R.kecocokan'!$B$57 -> Rendah | N32: ='B.kriteria & R.kecocokan'!$B$65 -> Rendah | O32: Tidak
A33: 30 | B33: 3523151403061477 | C33: SUDIRO | D33: 01 / 05 | E33: ='B.kriteria & R.kecocokan'!$B$25 -> Sedikit | F33: ='B.kriteria & R.kecocokan'!$B$35 -> Sangat Tinggi | G33: ='B.kriteria & R.kecocokan'!$B$41 -> Rendah | H33: ='B.kriteria & R.kecocokan'!$B$72 -> Rendah | I33: ='B.kriteria & R.kecocokan'!$B$95 -> Rendah | J33: ='B.kriteria & R.kecocokan'!$B$81 -> Tinggi | K33: ='B.kriteria & R.kecocokan'!$B$88 -> Sedang | L33: ='B.kriteria & R.kecocokan'!$B$51 -> Tinggi | M33: ='B.kriteria & R.kecocokan'!$B$59 -> Tinggi | N33: ='B.kriteria & R.kecocokan'!$B$65 -> Rendah | O33: Layak
A34: 31 | B34: 3523153112090244 | C34: SUYANTO | D34: 01 / 05 | E34: ='B.kriteria & R.kecocokan'!$B$24 -> Cukup | F34: ='B.kriteria & R.kecocokan'!$B$35 -> Sangat Tinggi | G34: ='B.kriteria & R.kecocokan'!$B$41 -> Rendah | H34: ='B.kriteria & R.kecocokan'!$B$72 -> Rendah | I34: ='B.kriteria & R.kecocokan'!$B$95 -> Rendah | J34: ='B.kriteria & R.kecocokan'!$B$80 -> Rendah | K34: ='B.kriteria & R.kecocokan'!$B$89 -> Sedikit | L34: ='B.kriteria & R.kecocokan'!$B$49 -> Rendah | M34: ='B.kriteria & R.kecocokan'!$B$58 -> Sedang | N34: ='B.kriteria & R.kecocokan'!$B$65 -> Rendah | O34: Layak
A35: 32 | B35: 3523141108840001 | C35: SUWANDI | D35: 01 / 05 | E35: ='B.kriteria & R.kecocokan'!$B$24 -> Cukup | F35: ='B.kriteria & R.kecocokan'!$B$34 -> Tinggi | G35: ='B.kriteria & R.kecocokan'!$B$41 -> Rendah | H35: ='B.kriteria & R.kecocokan'!$B$72 -> Rendah | I35: ='B.kriteria & R.kecocokan'!$B$95 -> Rendah | J35: ='B.kriteria & R.kecocokan'!$B$80 -> Rendah | K35: ='B.kriteria & R.kecocokan'!$B$88 -> Sedang | L35: ='B.kriteria & R.kecocokan'!$B$49 -> Rendah | M35: ='B.kriteria & R.kecocokan'!$B$57 -> Rendah | N35: ='B.kriteria & R.kecocokan'!$B$65 -> Rendah | O35: Tidak
A36: 33 | B36: 3523150107580287 | C36: LIK DJOYO | D36: 01 / 05 | E36: ='B.kriteria & R.kecocokan'!$B$25 -> Sedikit | F36: ='B.kriteria & R.kecocokan'!$B$34 -> Tinggi | G36: ='B.kriteria & R.kecocokan'!$B$43 -> Tinggi | H36: ='B.kriteria & R.kecocokan'!$B$72 -> Rendah | I36: ='B.kriteria & R.kecocokan'!$B$95 -> Rendah | J36: ='B.kriteria & R.kecocokan'!$B$81 -> Tinggi | K36: ='B.kriteria & R.kecocokan'!$B$90 -> Sangat Sedikit | L36: ='B.kriteria & R.kecocokan'!$B$49 -> Rendah | M36: ='B.kriteria & R.kecocokan'!$B$57 -> Rendah | N36: ='B.kriteria & R.kecocokan'!$B$65 -> Rendah | O36: Tidak
A37: 34 | B37: 3523150202500002 | C37: KARMADI | D37: 01 / 05 | E37: ='B.kriteria & R.kecocokan'!$B$23 -> Banyak | F37: ='B.kriteria & R.kecocokan'!$B$34 -> Tinggi | G37: ='B.kriteria & R.kecocokan'!$B$41 -> Rendah | H37: ='B.kriteria & R.kecocokan'!$B$72 -> Rendah | I37: ='B.kriteria & R.kecocokan'!$B$95 -> Rendah | J37: ='B.kriteria & R.kecocokan'!$B$81 -> Tinggi | K37: ='B.kriteria & R.kecocokan'!$B$90 -> Sangat Sedikit | L37: ='B.kriteria & R.kecocokan'!$B$49 -> Rendah | M37: ='B.kriteria & R.kecocokan'!$B$57 -> Rendah | N37: ='B.kriteria & R.kecocokan'!$B$65 -> Rendah | O37: Tidak
A38: 35 | B38: 3523150107510085 | C38: WIBOWO SLAMET | D38: 01 / 05 | E38: ='B.kriteria & R.kecocokan'!$B$25 -> Sedikit | F38: ='B.kriteria & R.kecocokan'!$B$34 -> Tinggi | G38: ='B.kriteria & R.kecocokan'!$B$41 -> Rendah | H38: ='B.kriteria & R.kecocokan'!$B$74 -> Tinggi | I38: ='B.kriteria & R.kecocokan'!$B$95 -> Rendah | J38: ='B.kriteria & R.kecocokan'!$B$81 -> Tinggi | K38: ='B.kriteria & R.kecocokan'!$B$90 -> Sangat Sedikit | L38: ='B.kriteria & R.kecocokan'!$B$50 -> Sedang | M38: ='B.kriteria & R.kecocokan'!$B$59 -> Tinggi | N38: ='B.kriteria & R.kecocokan'!$B$65 -> Rendah | O38: Layak
A39: 36 | B39: 3523151604600002 | C39: WINARTO | D39: 01 / 05 | E39: ='B.kriteria & R.kecocokan'!$B$24 -> Cukup | F39: ='B.kriteria & R.kecocokan'!$B$34 -> Tinggi | G39: ='B.kriteria & R.kecocokan'!$B$41 -> Rendah | H39: ='B.kriteria & R.kecocokan'!$B$72 -> Rendah | I39: ='B.kriteria & R.kecocokan'!$B$95 -> Rendah | J39: ='B.kriteria & R.kecocokan'!$B$80 -> Rendah | K39: ='B.kriteria & R.kecocokan'!$B$90 -> Sangat Sedikit | L39: ='B.kriteria & R.kecocokan'!$B$49 -> Rendah | M39: ='B.kriteria & R.kecocokan'!$B$57 -> Rendah | N39: ='B.kriteria & R.kecocokan'!$B$65 -> Rendah | O39: Tidak
A40: 37 | B40: 3523152603110001 | C40: HADI | D40: 01 / 05 | E40: ='B.kriteria & R.kecocokan'!$B$24 -> Cukup | F40: ='B.kriteria & R.kecocokan'!$B$34 -> Tinggi | G40: ='B.kriteria & R.kecocokan'!$B$41 -> Rendah | H40: ='B.kriteria & R.kecocokan'!$B$72 -> Rendah | I40: ='B.kriteria & R.kecocokan'!$B$95 -> Rendah | J40: ='B.kriteria & R.kecocokan'!$B$80 -> Rendah | K40: ='B.kriteria & R.kecocokan'!$B$88 -> Sedang | L40: ='B.kriteria & R.kecocokan'!$B$49 -> Rendah | M40: ='B.kriteria & R.kecocokan'!$B$57 -> Rendah | N40: ='B.kriteria & R.kecocokan'!$B$65 -> Rendah | O40: Tidak
A41: 38 | B41: 3523152212200001 | C41: NGATOLAN | D41: 01 / 05 | E41: ='B.kriteria & R.kecocokan'!$B$25 -> Sedikit | F41: ='B.kriteria & R.kecocokan'!$B$34 -> Tinggi | G41: ='B.kriteria & R.kecocokan'!$B$43 -> Tinggi | H41: ='B.kriteria & R.kecocokan'!$B$72 -> Rendah | I41: ='B.kriteria & R.kecocokan'!$B$95 -> Rendah | J41: ='B.kriteria & R.kecocokan'!$B$81 -> Tinggi | K41: ='B.kriteria & R.kecocokan'!$B$90 -> Sangat Sedikit | L41: ='B.kriteria & R.kecocokan'!$B$49 -> Rendah | M41: ='B.kriteria & R.kecocokan'!$B$57 -> Rendah | N41: ='B.kriteria & R.kecocokan'!$B$65 -> Rendah | O41: Tidak
...

Sheet hitung c4.5 2
A2: No. | B2: No KK | C2: Nama Kepala Keluarga | D2: RT / RW | E2: Penghasilan | F2: Luas Rumah | G2: Status Kepemilikan Rumah | H2: Sumber Air | I2: ibu Hamil / menyusui | J2: lansia | K2: jumlah tanggungan (Anak) | L2: jenis dinding | M2: jenis lantai | N2: jenis atap | O2: Keputusan | P2: Keputusan Prekdisi | Q2: node Akar | S2: jumlah | T2: Layak | U2: Tidak Layak | V2: Entrophy | W2: Gain
A3: 1 | B3: 3523151708700001 | C3: MUHAMMAD ABIDIN | D3: 01 / 05 | E3: ='B.kriteria & R.kecocokan'!$B$24 -> Cukup | F3: ='B.kriteria & R.kecocokan'!$B$34 -> Tinggi | G3: ='B.kriteria & R.kecocokan'!$B$41 -> Rendah | H3: ='B.kriteria & R.kecocokan'!$B$72 -> Rendah | I3: ='B.kriteria & R.kecocokan'!$B$95 -> Rendah | J3: ='B.kriteria & R.kecocokan'!$B$80 -> Rendah | K3: ='B.kriteria & R.kecocokan'!$B$89 -> Sedikit | L3: ='B.kriteria & R.kecocokan'!$B$49 -> Rendah | M3: ='B.kriteria & R.kecocokan'!$B$57 -> Rendah | N3: ='B.kriteria & R.kecocokan'!$B$65 -> Rendah | O3: Tidak | P3: =_xlfn.IFS(M3="Rendah","Tidak",M3="Tinggi","Layak",M3="sedang",IF(OR(K3="Sedang",K3="Sangat Sedikit"),"Layak",IF(F3="Sangat Tinggi","Layak"," Tidak"))) -> Tidak | Q3: total | S3: 93 | T3: =COUNTIF($O$3:$O$95,$O$88) -> 22 | U3: =COUNTIF($O$3:$O$95,$O$4) -> 71 | V3: =((-T3/S3)*IMLOG2(T3/S3))+((-U3/S3)*IMLOG2(U3/S3)) -> 0.78927127
A4: 2 | B4: 3523151403061494 | C4: MULYONO | D4: 01 / 05 | E4: ='B.kriteria & R.kecocokan'!$B$24 -> Cukup | F4: ='B.kriteria & R.kecocokan'!$B$34 -> Tinggi | G4: ='B.kriteria & R.kecocokan'!$B$41 -> Rendah | H4: ='B.kriteria & R.kecocokan'!$B$72 -> Rendah | I4: ='B.kriteria & R.kecocokan'!$B$95 -> Rendah | J4: ='B.kriteria & R.kecocokan'!$B$81 -> Tinggi | K4: ='B.kriteria & R.kecocokan'!$B$90 -> Sangat Sedikit | L4: ='B.kriteria & R.kecocokan'!$B$49 -> Rendah | M4: ='B.kriteria & R.kecocokan'!$B$57 -> Rendah | N4: ='B.kriteria & R.kecocokan'!$B$65 -> Rendah | O4: Tidak | P4: =_xlfn.IFS(M4="Rendah","Tidak",M4="Tinggi","Layak",M4="sedang",IF(OR(K4="Sedang",K4="Sangat Sedikit"),"Layak",IF(F4="Sangat Tinggi","Layak"," Tidak"))) -> Tidak | Q4: Penghasilan | W4: =$V$3 - ((S5/$S$3*V5) +(S6/$S$3*V6) +(S7/$S$3*V7)) -> 0.19047628
A5: 3 | B5: 3523150803680008 | C5: CAMPUN | D5: 01 / 05 | E5: ='B.kriteria & R.kecocokan'!$B$23 -> Banyak | F5: ='B.kriteria & R.kecocokan'!$B$34 -> Tinggi | G5: ='B.kriteria & R.kecocokan'!$B$41 -> Rendah | H5: ='B.kriteria & R.kecocokan'!$B$72 -> Rendah | I5: ='B.kriteria & R.kecocokan'!$B$95 -> Rendah | J5: ='B.kriteria & R.kecocokan'!$B$80 -> Rendah | K5: ='B.kriteria & R.kecocokan'!$B$90 -> Sangat Sedikit | L5: ='B.kriteria & R.kecocokan'!$B$49 -> Rendah | M5: ='B.kriteria & R.kecocokan'!$B$57 -> Rendah | N5: ='B.kriteria & R.kecocokan'!$B$65 -> Rendah | O5: Tidak | P5: =_xlfn.IFS(M5="Rendah","Tidak",M5="Tinggi","Layak",M5="sedang",IF(OR(K5="Sedang",K5="Sangat Sedikit"),"Layak",IF(F5="Sangat Tinggi","Layak"," Tidak"))) -> Tidak | R5: Banyak | S5: =COUNTIFS($E$3:$E$95,$E$73) -> 23 | T5: =COUNTIFS($E$3:$E$95,$E$87,$O$3:$O$95,$O$88) -> 0 | U5: =COUNTIFS($E$3:$E$95,$E$87,$O$3:$O$95,$O$11) -> 23 | V5: 0
A6: 4 | B6: 3523152312110002 | C6: SUNTONO | D6: 01 / 05 | E6: ='B.kriteria & R.kecocokan'!$B$24 -> Cukup | F6: ='B.kriteria & R.kecocokan'!$B$34 -> Tinggi | G6: ='B.kriteria & R.kecocokan'!$B$41 -> Rendah | H6: ='B.kriteria & R.kecocokan'!$B$72 -> Rendah | I6: ='B.kriteria & R.kecocokan'!$B$95 -> Rendah | J6: ='B.kriteria & R.kecocokan'!$B$80 -> Rendah | K6: ='B.kriteria & R.kecocokan'!$B$89 -> Sedikit | L6: ='B.kriteria & R.kecocokan'!$B$49 -> Rendah | M6: ='B.kriteria & R.kecocokan'!$B$57 -> Rendah | N6: ='B.kriteria & R.kecocokan'!$B$65 -> Rendah | O6: Tidak | P6: =_xlfn.IFS(M6="Rendah","Tidak",M6="Tinggi","Layak",M6="sedang",IF(OR(K6="Sedang",K6="Sangat Sedikit"),"Layak",IF(F6="Sangat Tinggi","Layak"," Tidak"))) -> Tidak | R6: cukup | S6: =COUNTIF($E$3:$E$95,$E$86) -> 35 | T6: =COUNTIFS($E$3:$E$95,$E$86,$O$3:$O$95,$O$90) -> 5 | U6: =COUNTIFS($E$3:$E$95,$E$86,$O$3:$O$95,$O$4) -> 30 | V6: =((-T6/S6)*IMLOG2(T6/S6))+((-U6/S6)*IMLOG2(U6/S6)) -> 0.59167278
A7: 5 | B7: =Penghasilan!B18 -> 3523152007120012 | C7: DEDDY MUDHIATAMA | D7: 02 / 05 | E7: ='B.kriteria & R.kecocokan'!$B$24 -> Cukup | F7: ='B.kriteria & R.kecocokan'!$B$34 -> Tinggi | G7: ='B.kriteria & R.kecocokan'!$B$41 -> Rendah | H7: ='B.kriteria & R.kecocokan'!$B$72 -> Rendah | I7: ='B.kriteria & R.kecocokan'!$B$95 -> Rendah | J7: ='B.kriteria & R.kecocokan'!$B$80 -> Rendah | K7: ='B.kriteria & R.kecocokan'!$B$88 -> Sedang | L7: ='B.kriteria & R.kecocokan'!$B$49 -> Rendah | M7: ='B.kriteria & R.kecocokan'!$B$57 -> Rendah | N7: ='B.kriteria & R.kecocokan'!$B$65 -> Rendah | O7: Tidak | P7: =_xlfn.IFS(M7="Rendah","Tidak",M7="Tinggi","Layak",M7="sedang",IF(OR(K7="Sedang",K7="Sangat Sedikit"),"Layak",IF(F7="Sangat Tinggi","Layak"," Tidak"))) -> Tidak | R7: sedikit | S7: =COUNTIFS($E$3:$E$95,$E$83) -> 35 | T7: =COUNTIFS($E$3:$E$95,$E$83,$O$3:$O$95,$O$85) -> 17 | U7: =COUNTIFS($E$3:$E$95,$E$83,$O$3:$O$95,$O$8) -> 18 | V7: =((-T7/S7)*IMLOG2(T7/S7))+((-U7/S7)*IMLOG2(U7/S7)) -> 0.99941106
A8: 6 | B8: 3523153010120005 | C8: IWAN SUGIYANTO | D8: 01 / 05 | E8: ='B.kriteria & R.kecocokan'!$B$23 -> Banyak | F8: ='B.kriteria & R.kecocokan'!$B$34 -> Tinggi | G8: ='B.kriteria & R.kecocokan'!$B$41 -> Rendah | H8: ='B.kriteria & R.kecocokan'!$B$72 -> Rendah | I8: ='B.kriteria & R.kecocokan'!$B$95 -> Rendah | J8: ='B.kriteria & R.kecocokan'!$B$80 -> Rendah | K8: ='B.kriteria & R.kecocokan'!$B$89 -> Sedikit | L8: ='B.kriteria & R.kecocokan'!$B$49 -> Rendah | M8: ='B.kriteria & R.kecocokan'!$B$57 -> Rendah | N8: ='B.kriteria & R.kecocokan'!$B$65 -> Rendah | O8: Tidak | P8: =_xlfn.IFS(M8="Rendah","Tidak",M8="Tinggi","Layak",M8="sedang",IF(OR(K8="Sedang",K8="Sangat Sedikit"),"Layak",IF(F8="Sangat Tinggi","Layak"," Tidak"))) -> Tidak | S8: =SUM(S5:S7) -> 93 | T8: =SUM(T5:T7) -> 22 | U8: =SUM(U5:U7) -> 71
A9: 7 | B9: 3523151005780008 | C9: MUNIR MUSTAQIM | D9: 01 / 05 | E9: ='B.kriteria & R.kecocokan'!$B$23 -> Banyak | F9: ='B.kriteria & R.kecocokan'!$B$34 -> Tinggi | G9: ='B.kriteria & R.kecocokan'!$B$41 -> Rendah | H9: ='B.kriteria & R.kecocokan'!$B$72 -> Rendah | I9: ='B.kriteria & R.kecocokan'!$B$95 -> Rendah | J9: ='B.kriteria & R.kecocokan'!$B$81 -> Tinggi | K9: ='B.kriteria & R.kecocokan'!$B$88 -> Sedang | L9: ='B.kriteria & R.kecocokan'!$B$49 -> Rendah | M9: ='B.kriteria & R.kecocokan'!$B$57 -> Rendah | N9: ='B.kriteria & R.kecocokan'!$B$65 -> Rendah | O9: Tidak | P9: =_xlfn.IFS(M9="Rendah","Tidak",M9="Tinggi","Layak",M9="sedang",IF(OR(K9="Sedang",K9="Sangat Sedikit"),"Layak",IF(F9="Sangat Tinggi","Layak"," Tidak"))) -> Tidak | Q9: Luas Rumah | W9: =$V$3 - ((S10/$S$3*V10) +(S11/$S$3*V11)) -> 0.10819547
A10: 8 | B10: 3523155002670004 | C10: KASMINI | D10: 01 / 05 | E10: ='B.kriteria & R.kecocokan'!$B$24 -> Cukup | F10: ='B.kriteria & R.kecocokan'!$B$34 -> Tinggi | G10: ='B.kriteria & R.kecocokan'!$B$41 -> Rendah | H10: ='B.kriteria & R.kecocokan'!$B$72 -> Rendah | I10: ='B.kriteria & R.kecocokan'!$B$95 -> Rendah | J10: ='B.kriteria & R.kecocokan'!$B$80 -> Rendah | K10: ='B.kriteria & R.kecocokan'!$B$89 -> Sedikit | L10: ='B.kriteria & R.kecocokan'!$B$49 -> Rendah | M10: ='B.kriteria & R.kecocokan'!$B$57 -> Rendah | N10: ='B.kriteria & R.kecocokan'!$B$65 -> Rendah | O10: Tidak | P10: =_xlfn.IFS(M10="Rendah","Tidak",M10="Tinggi","Layak",M10="sedang",IF(OR(K10="Sedang",K10="Sangat Sedikit"),"Layak",IF(F10="Sangat Tinggi","Layak"," Tidak"))) -> Tidak | R10: tinggi | S10: =COUNTIFS($F$3:$F$95,$F$3) -> 77 | T10: =COUNTIFS($F$3:$F$95,$F$3,$O$3:$O$95,$O$81) -> 12 | U10: =COUNTIFS($F$3:$F$95,$F$3,$O$3:$O$95,$O$4) -> 65 | V10: =((-T10/S10)*IMLOG2(T10/S10))+((-U10/S10)*IMLOG2(U10/S10)) -> 0.6242741
A11: 9 | B11: =Penghasilan!B66 -> No KK | C11: MOKH YUSUF | D11: 01 / 05 | E11: ='B.kriteria & R.kecocokan'!$B$24 -> Cukup | F11: ='B.kriteria & R.kecocokan'!$B$34 -> Tinggi | G11: ='B.kriteria & R.kecocokan'!$B$43 -> Tinggi | H11: ='B.kriteria & R.kecocokan'!$B$72 -> Rendah | I11: ='B.kriteria & R.kecocokan'!$B$95 -> Rendah | J11: ='B.kriteria & R.kecocokan'!$B$80 -> Rendah | K11: ='B.kriteria & R.kecocokan'!$B$88 -> Sedang | L11: ='B.kriteria & R.kecocokan'!$B$49 -> Rendah | M11: ='B.kriteria & R.kecocokan'!$B$57 -> Rendah | N11: ='B.kriteria & R.kecocokan'!$B$65 -> Rendah | O11: Tidak | P11: =_xlfn.IFS(M11="Rendah","Tidak",M11="Tinggi","Layak",M11="sedang",IF(OR(K11="Sedang",K11="Sangat Sedikit"),"Layak",IF(F11="Sangat Tinggi","Layak"," Tidak"))) -> Tidak | R11: Sangat tinggi | S11: =COUNTIFS($F$3:$F$95,$F$16) -> 16 | T11: =COUNTIFS($F$3:$F$95,$F$16,$O$3:$O$95,$O$13) -> 10 | U11: =COUNTIFS($F$3:$F$95,$F$16,$O$3:$O$95,$O$9) -> 6 | V11: =((-T11/S11)*IMLOG2(T11/S11))+((-U11/S11)*IMLOG2(U11/S11)) -> 0.954434
A12: 10 | B12: 3523151403061495 | C12: TARNO | D12: 01 / 05 | E12: ='B.kriteria & R.kecocokan'!$B$24 -> Cukup | F12: ='B.kriteria & R.kecocokan'!$B$34 -> Tinggi | G12: ='B.kriteria & R.kecocokan'!$B$41 -> Rendah | H12: ='B.kriteria & R.kecocokan'!$B$72 -> Rendah | I12: ='B.kriteria & R.kecocokan'!$B$95 -> Rendah | J12: ='B.kriteria & R.kecocokan'!$B$81 -> Tinggi | K12: ='B.kriteria & R.kecocokan'!$B$90 -> Sangat Sedikit | L12: ='B.kriteria & R.kecocokan'!$B$49 -> Rendah | M12: ='B.kriteria & R.kecocokan'!$B$57 -> Rendah | N12: ='B.kriteria & R.kecocokan'!$B$65 -> Rendah | O12: Layak | P12: =_xlfn.IFS(M12="Rendah","Tidak",M12="Tinggi","Layak",M12="sedang",IF(OR(K12="Sedang",K12="Sangat Sedikit"),"Layak",IF(F12="Sangat Tinggi","Layak"," Tidak"))) -> Tidak | S12: =SUM(S10:S11) -> 93 | T12: =SUM(T10:T11) -> 22 | U12: =SUM(U10:U11) -> 71
A13: 11 | B13: 3523151403061490 | C13: MURSID | D13: 01 / 05 | E13: ='B.kriteria & R.kecocokan'!$B$25 -> Sedikit | F13: ='B.kriteria & R.kecocokan'!$B$34 -> Tinggi | G13: ='B.kriteria & R.kecocokan'!$B$41 -> Rendah | H13: ='B.kriteria & R.kecocokan'!$B$72 -> Rendah | I13: ='B.kriteria & R.kecocokan'!$B$95 -> Rendah | J13: ='B.kriteria & R.kecocokan'!$B$81 -> Tinggi | K13: ='B.kriteria & R.kecocokan'!$B$90 -> Sangat Sedikit | L13: ='B.kriteria & R.kecocokan'!$B$50 -> Sedang | M13: ='B.kriteria & R.kecocokan'!$B$58 -> Sedang | N13: ='B.kriteria & R.kecocokan'!$B$66 -> Sedang | O13: Layak | P13: =_xlfn.IFS(M13="Rendah","Tidak",M13="Tinggi","Layak",M13="sedang",IF(OR(K13="Sedang",K13="Sangat Sedikit"),"Layak",IF(F13="Sangat Tinggi","Layak"," Tidak"))) -> Layak | Q13: Status pemilikan rumah | W13: =$V$3 - ((S14/$S$3*V14) +(S15/$S$3*V15)) -> 0.049504251
A14: 12 | B14: 3523151403061489 | C14: ABDUL MAJID | D14: 01 / 05 | E14: ='B.kriteria & R.kecocokan'!$B$24 -> Cukup | F14: ='B.kriteria & R.kecocokan'!$B$34 -> Tinggi | G14: ='B.kriteria & R.kecocokan'!$B$41 -> Rendah | H14: ='B.kriteria & R.kecocokan'!$B$72 -> Rendah | I14: ='B.kriteria & R.kecocokan'!$B$95 -> Rendah | J14: ='B.kriteria & R.kecocokan'!$B$81 -> Tinggi | K14: ='B.kriteria & R.kecocokan'!$B$90 -> Sangat Sedikit | L14: ='B.kriteria & R.kecocokan'!$B$49 -> Rendah | M14: ='B.kriteria & R.kecocokan'!$B$57 -> Rendah | N14: ='B.kriteria & R.kecocokan'!$B$65 -> Rendah | O14: Tidak | P14: =_xlfn.IFS(M14="Rendah","Tidak",M14="Tinggi","Layak",M14="sedang",IF(OR(K14="Sedang",K14="Sangat Sedikit"),"Layak",IF(F14="Sangat Tinggi","Layak"," Tidak"))) -> Tidak | R14: Rendah | S14: =COUNTIFS($G$3:$G$95,$G$3) -> 82 | T14: =COUNTIFS($G$3:$G$95,$G$3,$O$3:$O$95,$O$13) -> 22 | U14: =COUNTIFS($G$3:$G$95,$G$3,$O$3:$O$95,$O$11) -> 60 | V14: =((-T14/S14)*IMLOG2(T14/S14))+((-U14/S14)*IMLOG2(U14/S14)) -> 0.83900406
A15: 13 | B15: 3523151210160002 | C15: SUGENG WAHONO | D15: 01 / 05 | E15: ='B.kriteria & R.kecocokan'!$B$24 -> Cukup | F15: ='B.kriteria & R.kecocokan'!$B$34 -> Tinggi | G15: ='B.kriteria & R.kecocokan'!$B$43 -> Tinggi | H15: ='B.kriteria & R.kecocokan'!$B$72 -> Rendah | I15: ='B.kriteria & R.kecocokan'!$B$95 -> Rendah | J15: ='B.kriteria & R.kecocokan'!$B$80 -> Rendah | K15: ='B.kriteria & R.kecocokan'!$B$88 -> Sedang | L15: ='B.kriteria & R.kecocokan'!$B$49 -> Rendah | M15: ='B.kriteria & R.kecocokan'!$B$57 -> Rendah | N15: ='B.kriteria & R.kecocokan'!$B$65 -> Rendah | O15: Tidak | P15: =_xlfn.IFS(M15="Rendah","Tidak",M15="Tinggi","Layak",M15="sedang",IF(OR(K15="Sedang",K15="Sangat Sedikit"),"Layak",IF(F15="Sangat Tinggi","Layak"," Tidak"))) -> Tidak | R15: tinggi | S15: =COUNTIFS($G$3:$G$95,$G$89) -> 11 | T15: =COUNTIFS($G$3:$G$95,$G$29,$O$3:$O$95,$O$13) -> 0 | U15: =COUNTIFS($G$3:$G$95,$G$29,$O$3:$O$95,$O$7) -> 11 | V15: 0
A16: 14 | B16: 3523153012090392 | C16: TAMIN | D16: 01 / 05 | E16: ='B.kriteria & R.kecocokan'!$B$24 -> Cukup | F16: ='B.kriteria & R.kecocokan'!$B$35 -> Sangat Tinggi | G16: ='B.kriteria & R.kecocokan'!$B$41 -> Rendah | H16: ='B.kriteria & R.kecocokan'!$B$72 -> Rendah | I16: ='B.kriteria & R.kecocokan'!$B$95 -> Rendah | J16: ='B.kriteria & R.kecocokan'!$B$80 -> Rendah | K16: ='B.kriteria & R.kecocokan'!$B$89 -> Sedikit | L16: ='B.kriteria & R.kecocokan'!$B$49 -> Rendah | M16: ='B.kriteria & R.kecocokan'!$B$58 -> Sedang | N16: ='B.kriteria & R.kecocokan'!$B$65 -> Rendah | O16: Tidak | P16: =_xlfn.IFS(M16="Rendah","Tidak",M16="Tinggi","Layak",M16="sedang",IF(OR(K16="Sedang",K16="Sangat Sedikit"),"Layak",IF(F16="Sangat Tinggi","Layak"," Tidak"))) -> Layak | S16: =SUM(S14:S15) -> 93 | T16: =SUM(T14:T15) -> 22 | U16: =SUM(U14:U15) -> 71
A17: 15 | B17: 3523153112090174 | C17: ABDUH NAHLIAN | D17: 01 / 05 | E17: ='B.kriteria & R.kecocokan'!$B$23 -> Banyak | F17: ='B.kriteria & R.kecocokan'!$B$35 -> Sangat Tinggi | G17: ='B.kriteria & R.kecocokan'!$B$41 -> Rendah | H17: ='B.kriteria & R.kecocokan'!$B$72 -> Rendah | I17: ='B.kriteria & R.kecocokan'!$B$95 -> Rendah | J17: ='B.kriteria & R.kecocokan'!$B$80 -> Rendah | K17: ='B.kriteria & R.kecocokan'!$B$88 -> Sedang | L17: ='B.kriteria & R.kecocokan'!$B$49 -> Rendah | M17: ='B.kriteria & R.kecocokan'!$B$57 -> Rendah | N17: ='B.kriteria & R.kecocokan'!$B$65 -> Rendah | O17: Tidak | P17: =_xlfn.IFS(M17="Rendah","Tidak",M17="Tinggi","Layak",M17="sedang",IF(OR(K17="Sedang",K17="Sangat Sedikit"),"Layak",IF(F17="Sangat Tinggi","Layak"," Tidak"))) -> Tidak | Q17: sumber air | W17: =$V$3 - ((S18/$S$3*V18) +(S19/$S$3*V19)) -> 0.022636986
A18: 16 | B18: 3523151403061485 | C18: TARMUDJI | D18: 01 / 05 | E18: ='B.kriteria & R.kecocokan'!$B$24 -> Cukup | F18: ='B.kriteria & R.kecocokan'!$B$34 -> Tinggi | G18: ='B.kriteria & R.kecocokan'!$B$41 -> Rendah | H18: ='B.kriteria & R.kecocokan'!$B$72 -> Rendah | I18: ='B.kriteria & R.kecocokan'!$B$95 -> Rendah | J18: ='B.kriteria & R.kecocokan'!$B$81 -> Tinggi | K18: ='B.kriteria & R.kecocokan'!$B$90 -> Sangat Sedikit | L18: ='B.kriteria & R.kecocokan'!$B$49 -> Rendah | M18: ='B.kriteria & R.kecocokan'!$B$57 -> Rendah | N18: ='B.kriteria & R.kecocokan'!$B$65 -> Rendah | O18: Tidak | P18: =_xlfn.IFS(M18="Rendah","Tidak",M18="Tinggi","Layak",M18="sedang",IF(OR(K18="Sedang",K18="Sangat Sedikit"),"Layak",IF(F18="Sangat Tinggi","Layak"," Tidak"))) -> Tidak | R18: Rendah | S18: =COUNTIFS($H$3:$H$95,$H$3) -> 92 | T18: =COUNTIFS($H$3:$H$95,$H$3,$O$3:$O$95,$O$90) -> 21 | U18: =COUNTIFS($H$3:$H$95,$H$3,$O$3:$O$95,$O$9) -> 71 | V18: =((-T18/S18)*IMLOG2(T18/S18))+((-U18/S18)*IMLOG2(U18/S18)) -> 0.77496727
A19: 17 | B19: 3523150305120003 | C19: SUWANTO | D19: 01 / 05 | E19: ='B.kriteria & R.kecocokan'!$B$24 -> Cukup | F19: ='B.kriteria & R.kecocokan'!$B$35 -> Sangat Tinggi | G19: ='B.kriteria & R.kecocokan'!$B$41 -> Rendah | H19: ='B.kriteria & R.kecocokan'!$B$72 -> Rendah | I19: ='B.kriteria & R.kecocokan'!$B$95 -> Rendah | J19: ='B.kriteria & R.kecocokan'!$B$80 -> Rendah | K19: ='B.kriteria & R.kecocokan'!$B$88 -> Sedang | L19: ='B.kriteria & R.kecocokan'!$B$51 -> Tinggi | M19: ='B.kriteria & R.kecocokan'!$B$58 -> Sedang | N19: ='B.kriteria & R.kecocokan'!$B$65 -> Rendah | O19: Layak | P19: =_xlfn.IFS(M19="Rendah","Tidak",M19="Tinggi","Layak",M19="sedang",IF(OR(K19="Sedang",K19="Sangat Sedikit"),"Layak",IF(F19="Sangat Tinggi","Layak"," Tidak"))) -> Layak | R19: tinggi | S19: =COUNTIFS($H$3:$H$95,$H$37) -> 1 | T19: =COUNTIFS($H$3:$H$95,$H$37,$O$3:$O$95,$O$33) -> 1 | U19: =COUNTIFS($H$3:$H$95,$H$37,$O$3:$O$95,$O$11) -> 0 | V19: 0
A20: 18 | B20: 3523153112090228 | C20: KASIMO | D20: 01 / 05 | E20: ='B.kriteria & R.kecocokan'!$B$24 -> Cukup | F20: ='B.kriteria & R.kecocokan'!$B$35 -> Sangat Tinggi | G20: ='B.kriteria & R.kecocokan'!$B$41 -> Rendah | H20: ='B.kriteria & R.kecocokan'!$B$72 -> Rendah | I20: ='B.kriteria & R.kecocokan'!$B$95 -> Rendah | J20: ='B.kriteria & R.kecocokan'!$B$80 -> Rendah | K20: ='B.kriteria & R.kecocokan'!$B$88 -> Sedang | L20: ='B.kriteria & R.kecocokan'!$B$50 -> Sedang | M20: ='B.kriteria & R.kecocokan'!$B$58 -> Sedang | N20: ='B.kriteria & R.kecocokan'!$B$65 -> Rendah | O20: Layak | P20: =_xlfn.IFS(M20="Rendah","Tidak",M20="Tinggi","Layak",M20="sedang",IF(OR(K20="Sedang",K20="Sangat Sedikit"),"Layak",IF(F20="Sangat Tinggi","Layak"," Tidak"))) -> Layak | S20: =SUM(S18:S19) -> 93 | T20: =SUM(T18:T19) -> 22 | U20: =SUM(U18:U19) -> 71
A21: 19 | B21: 3523152608190006 | C21: KASMINAH | D21: 01 / 05 | E21: ='B.kriteria & R.kecocokan'!$B$25 -> Sedikit | F21: ='B.kriteria & R.kecocokan'!$B$34 -> Tinggi | G21: ='B.kriteria & R.kecocokan'!$B$41 -> Rendah | H21: ='B.kriteria & R.kecocokan'!$B$72 -> Rendah | I21: ='B.kriteria & R.kecocokan'!$B$95 -> Rendah | J21: ='B.kriteria & R.kecocokan'!$B$81 -> Tinggi | K21: ='B.kriteria & R.kecocokan'!$B$90 -> Sangat Sedikit | L21: ='B.kriteria & R.kecocokan'!$B$49 -> Rendah | M21: ='B.kriteria & R.kecocokan'!$B$58 -> Sedang | N21: ='B.kriteria & R.kecocokan'!$B$65 -> Rendah | O21: Layak | P21: =_xlfn.IFS(M21="Rendah","Tidak",M21="Tinggi","Layak",M21="sedang",IF(OR(K21="Sedang",K21="Sangat Sedikit"),"Layak",IF(F21="Sangat Tinggi","Layak"," Tidak"))) -> Layak | Q21: ibu hamil / menyusui | W21: =$V$3 - ((S22/$S$3*V22) +(S23/$S$3*V23)) -> 0.0084795614
A22: 20 | B22: 3523150603820007 | C22: DIDIK PRIANTO | D22: 01 / 05 | E22: ='B.kriteria & R.kecocokan'!$B$24 -> Cukup | F22: ='B.kriteria & R.kecocokan'!$B$34 -> Tinggi | G22: ='B.kriteria & R.kecocokan'!$B$41 -> Rendah | H22: ='B.kriteria & R.kecocokan'!$B$72 -> Rendah | I22: ='B.kriteria & R.kecocokan'!$B$95 -> Rendah | J22: ='B.kriteria & R.kecocokan'!$B$80 -> Rendah | K22: ='B.kriteria & R.kecocokan'!$B$89 -> Sedikit | L22: ='B.kriteria & R.kecocokan'!$B$49 -> Rendah | M22: ='B.kriteria & R.kecocokan'!$B$58 -> Sedang | N22: ='B.kriteria & R.kecocokan'!$B$65 -> Rendah | O22: Tidak | P22: =_xlfn.IFS(M22="Rendah","Tidak",M22="Tinggi","Layak",M22="sedang",IF(OR(K22="Sedang",K22="Sangat Sedikit"),"Layak",IF(F22="Sangat Tinggi","Layak"," Tidak"))) -> Tidak | R22: Rendah | S22: =COUNTIFS($I$3:$I$95,$I$88) -> 91 | T22: =COUNTIFS($I$3:$I$95,$I$88,$O$3:$O$95,$O$13) -> 22 | U22: =COUNTIFS($I$3:$I$95,$I$88,$O$3:$O$95,$O$8) -> 69 | V22: =((-T22/S22)*IMLOG2(T22/S22))+((-U22/S22)*IMLOG2(U22/S22)) -> 0.79795197
A23: 21 | B23: 3523151403061487 | C23: DASMIATI | D23: 01 / 05 | E23: ='B.kriteria & R.kecocokan'!$B$25 -> Sedikit | F23: ='B.kriteria & R.kecocokan'!$B$35 -> Sangat Tinggi | G23: ='B.kriteria & R.kecocokan'!$B$41 -> Rendah | H23: ='B.kriteria & R.kecocokan'!$B$72 -> Rendah | I23: ='B.kriteria & R.kecocokan'!$B$95 -> Rendah | J23: ='B.kriteria & R.kecocokan'!$B$81 -> Tinggi | K23: ='B.kriteria & R.kecocokan'!$B$90 -> Sangat Sedikit | L23: ='B.kriteria & R.kecocokan'!$B$49 -> Rendah | M23: ='B.kriteria & R.kecocokan'!$B$58 -> Sedang | N23: ='B.kriteria & R.kecocokan'!$B$65 -> Rendah | O23: Layak | P23: =_xlfn.IFS(M23="Rendah","Tidak",M23="Tinggi","Layak",M23="sedang",IF(OR(K23="Sedang",K23="Sangat Sedikit"),"Layak",IF(F23="Sangat Tinggi","Layak"," Tidak"))) -> Layak | R23: tinggi | S23: =COUNTIFS($I$3:$I$95,$I$82) -> 2 | T23: =COUNTIFS($I$3:$I$95,$I$82,$O$3:$O$95,$O$13) -> 0 | U23: =COUNTIFS($I$3:$I$95,$I$82,$O$3:$O$95,$O$9) -> 2 | V23: 0
A24: 22 | B24: 3523153112090184 | C24: IMAM KHOIRI | D24: 01 / 05 | E24: ='B.kriteria & R.kecocokan'!$B$23 -> Banyak | F24: ='B.kriteria & R.kecocokan'!$B$34 -> Tinggi | G24: ='B.kriteria & R.kecocokan'!$B$41 -> Rendah | H24: ='B.kriteria & R.kecocokan'!$B$72 -> Rendah | I24: ='B.kriteria & R.kecocokan'!$B$95 -> Rendah | J24: ='B.kriteria & R.kecocokan'!$B$80 -> Rendah | K24: ='B.kriteria & R.kecocokan'!$B$88 -> Sedang | L24: ='B.kriteria & R.kecocokan'!$B$49 -> Rendah | M24: ='B.kriteria & R.kecocokan'!$B$57 -> Rendah | N24: ='B.kriteria & R.kecocokan'!$B$65 -> Rendah | O24: Tidak | P24: =_xlfn.IFS(M24="Rendah","Tidak",M24="Tinggi","Layak",M24="sedang",IF(OR(K24="Sedang",K24="Sangat Sedikit"),"Layak",IF(F24="Sangat Tinggi","Layak"," Tidak"))) -> Tidak | S24: =SUM(S22:S23) -> 93 | T24: =SUM(T22:T23) -> 22 | U24: =SUM(U22:U23) -> 71
A25: 23 | B25: 3523151403061482 | C25: IMAM TOKO | D25: 01 / 05 | E25: ='B.kriteria & R.kecocokan'!$B$24 -> Cukup | F25: ='B.kriteria & R.kecocokan'!$B$34 -> Tinggi | G25: ='B.kriteria & R.kecocokan'!$B$41 -> Rendah | H25: ='B.kriteria & R.kecocokan'!$B$72 -> Rendah | I25: ='B.kriteria & R.kecocokan'!$B$95 -> Rendah | J25: ='B.kriteria & R.kecocokan'!$B$80 -> Rendah | K25: ='B.kriteria & R.kecocokan'!$B$88 -> Sedang | L25: ='B.kriteria & R.kecocokan'!$B$49 -> Rendah | M25: ='B.kriteria & R.kecocokan'!$B$57 -> Rendah | N25: ='B.kriteria & R.kecocokan'!$B$65 -> Rendah | O25: Tidak | P25: =_xlfn.IFS(M25="Rendah","Tidak",M25="Tinggi","Layak",M25="sedang",IF(OR(K25="Sedang",K25="Sangat Sedikit"),"Layak",IF(F25="Sangat Tinggi","Layak"," Tidak"))) -> Tidak | Q25: lansia | W25: =$V$3 - ((S26/$S$3*V26) +(S27/$S$3*V27)) -> 0.09402421
A26: 24 | B26: 3523150212140009 | C26: TUTIK | D26: 01 / 05 | E26: ='B.kriteria & R.kecocokan'!$B$24 -> Cukup | F26: ='B.kriteria & R.kecocokan'!$B$35 -> Sangat Tinggi | G26: ='B.kriteria & R.kecocokan'!$B$41 -> Rendah | H26: ='B.kriteria & R.kecocokan'!$B$72 -> Rendah | I26: ='B.kriteria & R.kecocokan'!$B$95 -> Rendah | J26: ='B.kriteria & R.kecocokan'!$B$80 -> Rendah | K26: ='B.kriteria & R.kecocokan'!$B$88 -> Sedang | L26: ='B.kriteria & R.kecocokan'!$B$49 -> Rendah | M26: ='B.kriteria & R.kecocokan'!$B$57 -> Rendah | N26: ='B.kriteria & R.kecocokan'!$B$65 -> Rendah | O26: Tidak | P26: =_xlfn.IFS(M26="Rendah","Tidak",M26="Tinggi","Layak",M26="sedang",IF(OR(K26="Sedang",K26="Sangat Sedikit"),"Layak",IF(F26="Sangat Tinggi","Layak"," Tidak"))) -> Tidak | R26: rendah | S26: =COUNTIFS($J$3:$J$95,$J$3) -> 55 | T26: =COUNTIFS($J$3:$J$95,$J$3,$O$3:$O$95,$O$12) -> 6 | U26: =COUNTIFS($J$3:$J$95,$J$3,$O$3:$O$95,$O$22) -> 49 | V26: =((-T26/S26)*IMLOG2(T26/S26))+((-U26/S26)*IMLOG2(U26/S26)) -> 0.49716776
